Workbook
Name Atores: Atores!$B$13:$C$17
Name ITEC: Fatores!$E$22
Name FCAMB: Fatores!$G$36
Name CUC: UC!$D$13:$D$39
Name TotalDiasUteisProjeto: Releases!$E$11
Name PTA: Atores!$D$10
Name _Toc112831755: UC!$B$13
Name UC: UC!$A$12:$C$39
Name PTUC: UC!$D$10
Name FCTEC: Fatores!$E$22
Name TotalHorasProjeto: Geral!$J$21

Sheet Geral
B3: Estimativa de Esforço de Projeto baseado em Pontos de Caso de Uso (vs 1.1)
B6: Projeto: | D6: Arena Local
B7: Responsável: | D7: Alex, Cauã, Laura, Matheus
B8: Data: | D8: 46315 | F8: Vs. do Documento: | H8: 1.0
B12: Resultado da Estimativa | G12: Esforço por fases | J12: Horas | K12: %
B13: Total de Pontos de Caso de Uso(tamanho) | E13: =Atores!D10+UC!D10 -> 100 | G13: Fase de Prospecção | J13: =$E$13*$E$14*K13 -> 16.600791 | K13: =dadoshistoricos!E31 -> 0.041501976
B14: Homens/hora por PCU | E14: =dadoshistoricos!L30 -> 4 | G14: Fase de Análise | J14: =$E$13*$E$14*K14 -> 58.498024 | K14: =dadoshistoricos!F31*0.8 -> 0.14624506
G15: Fase de Projeto | J15: =$E$13*$E$14*K15 -> 14.624506 | K15: =dadoshistoricos!F31*0.2 -> 0.036561265
G16: Fase de Planejamento | J16: =$E$13*$E$14*K16 -> 23.320158 | K16: =dadoshistoricos!G31 -> 0.058300395
G17: Fase de Desenvolvimento | J17: =$E$13*$E$14*K17 -> 197.62846 | K17: =dadoshistoricos!H31 -> 0.49407115
G18: Processo de Monitoramento e Controle | J18: =$E$13*$E$14*K18 -> 48.221344 | K18: =dadoshistoricos!J31 -> 0.12055336
G19: Fase de Fechamento | J19: =$E$13*$E$14*K19 -> 15.810277 | K19: =dadoshistoricos!I31 -> 0.039525692
B20: Instruções para realizar a estimativa do Projeto: | G20: Processo Controle de mudanças | J20: =$E$13*$E$14*K20 -> 25.296443 | K20: =dadoshistoricos!K31 -> 0.063241107
G21: Total de horas do Projeto | J21: =SUM(J13:J20) -> 400 | K21: =SUM(K13:K20) -> 1
B22: 1) Preencha a Planilha Atores indicando os atores(usuários do sistema) e a sua complexidade.
B23: 2) Preencha a Planilha UC indicando os casos de uso e quantidade de transações.
B24: 3) Preencha a Planilha Fatores, com os fatores de complexidade ambiental e técnicos do Projeto.
B25: 4) Após a execução dos passos anteriores, os resultados finais encontram-se na Planilha Geral.
B27: Obs.:
B28: Existem informações ocultas na células que possuem marcação(pontos coloridos). Posicione o mouse sobre a celula para visualizar a informação.

Sheet Atores
B2: Atores do Projeto
B6: Complexidade do Ator | C6: Peso | D6: Qt. de Atores
B7: Simples | C7: 1 | D7: =COUNTIF(Atores,B7) -> 1
B8: Médio | C8: 2 | D8: =COUNTIF(Atores,B8) -> 0
B9: Complexo | C9: 3 | D9: =COUNTIF(Atores,B9) -> 3
C10: Peso Total Atores = | D10: =(C7*D7)+(C8*D8)+(C9*D9) -> 10
B13: Atores | C13: Complexidade
B14: Organizador / Liga amadora | C14: Complexo
B15: Usuário (torcedor, atleta ou capitão de equipe) | C15: Complexo
B16: Administrador do sistema | C16: Complexo
B17: Serviço de envio de avisos (e-mail/push) | C17: Simples
B18: Total | C18: =SUBTOTAL(103,C14:C17) -> 4

Sheet UC
B2: Casos de Uso do Projeto
B6: Complexidade do Caso de Uso | C6: Peso | D6: Qt. de UC
B7: Simples | C7: 5 | D7: =COUNTIF(CUC,B7) -> 1
B8: Médio | C8: 10 | D8: =COUNTIF(CUC,B8) -> 7
B9: Complexo | C9: 15 | D9: =COUNTIF(CUC,B9) -> 1
C10: Peso Total UC | D10: =(C7*D7)+(C8*D8)+(C9*D9) -> 90
A12: ID | B12: Nome do RFC ou RFS | C12: Nro Entidades | D12: Complexidade | E12: Discriminar Transações(opcional)
B13: [RFC01] Manter Usuário (cadastro, perfil e autenticação) | C13: 3 | D13: =IF(C13<4,"Simples",(IF(C13>5,"Complexo","Médio"))) -> Simples | E13: Incluir, alterar, consultar, excluir usuário; login/logout. Entidades: Usuário, Perfil, Cidade | O13: 1
B14: [RFC02] Manter Organizador / Liga | C14: 4 | D14: =IF(C14<4,"Simples",(IF(C14>5,"Complexo","Médio"))) -> Médio | E14: Incluir, alterar, consultar, excluir organizador. Entidades: Organizador, Usuário, Cidade, Modalidade | O14: 2
B15: [RFC03] Manter Campeonato (com filtros por cidade, modalidade, categoria e data) | C15: 6 | D15: =IF(C15<4,"Simples",(IF(C15>5,"Complexo","Médio"))) -> Complexo | E15: Incluir, alterar, consultar (filtros), excluir. Entidades: Campeonato, Organizador, Modalidade, Categoria, Cidade, Local | O15: 3
B16: [RFC04] Manter Equipe | C16: 5 | D16: =IF(C16<4,"Simples",(IF(C16>5,"Complexo","Médio"))) -> Médio | E16: Incluir, alterar, consultar, excluir equipe. Entidades: Equipe, Usuário (responsável), Modalidade, Categoria, Cidade | O16: 4
B17: [RFC05] Manter Partida (tabela de jogos) | C17: 4 | D17: =IF(C17<4,"Simples",(IF(C17>5,"Complexo","Médio"))) -> Médio | E17: Incluir, alterar, consultar, excluir partida. Entidades: Partida, Campeonato, Equipe, Local | O17: 5
B18: [RFC06] Manter Resultado de Partida | C18: 4 | D18: =IF(C18<4,"Simples",(IF(C18>5,"Complexo","Médio"))) -> Médio | E18: Registrar, alterar, consultar, excluir resultado. Entidades: Resultado, Partida, Equipe, Campeonato | O18: 6
B19: [RFC07] Manter Inscrição de Equipe em Campeonato | C19: 5 | D19: =IF(C19<4,"Simples",(IF(C19>5,"Complexo","Médio"))) -> Médio | E19: Inscrever, alterar, consultar, cancelar inscrição. Entidades: Inscrição, Equipe, Campeonato, Categoria, Usuário | O19: 7
B20: [RFC08] Manter Aviso de Evento (eventos próximos) | C20: 5 | D20: =IF(C20<4,"Simples",(IF(C20>5,"Complexo","Médio"))) -> Médio | E20: Incluir, alterar, consultar, excluir aviso; dispara envio. Entidades: Aviso, Usuário, Campeonato, Cidade, Modalidade | O20: 8
B21: [RFR01] Relatório de Tabela de Jogos e Classificação | C21: 5 | D21: =IF(C21<4,"Simples",(IF(C21>5,"Complexo","Médio"))) -> Médio | E21: Consulta/relatório por campeonato. Entidades: Campeonato, Partida, Resultado, Equipe, Categoria | O21: 9
O22: 10
O23: 11
O24: 12
O25: 13
O26: 14
O27: 15
O28: 16
O29: 17
O30: 18
O31: 19
O32: 21
O33: 22
... O39: 28
A40: Total | B40: =SUBTOTAL(103,B13:B39) -> 9 | O40: 29
O41: 30
O42: 31
O43: 32
O44: 33
O45: 34
O46: 35
O47: 36
O48: 37
O49: 38
O50: 39
...

Sheet Fatores
B4: Fatores de Complexidade
B7: Influência Tecnológica
B8: ID | C8: Descrição | D8: Peso | E8: Influência | H8: Justificativa / premissa
B9: T01 | C9: Sistemas Distribuídos | D9: 2 | E9: 3 | H9: Aplicação web cliente-servidor com serviço de envio de avisos
B10: T02 | C10: Tempo de resposta | D10: 1 | E10: 3 | H10: Filtros e tabelas precisam responder rápido
B11: T03 | C11: Grau de escolaridade do usuário final | D11: 1 | E11: 3 | H11: Público geral, sem exigência de formação
B12: T04 | C12: Processamento interno complexo | D12: 1 | E12: 2 | H12: Cálculo de classificação a partir dos resultados
B13: T05 | C13: Reusabilidade do código em outras aplicações | D13: 1 | E13: 2 | H13: Cadastros básicos poderiam ser reaproveitados
B14: T06 | C14: Facilidade de instalação | D14: 0.5 | E14: 2 | H14: Hospedagem web, sem instalação pelo usuário
B15: T07 | C15: Usabilidade (facilidade operacional) | D15: 0.5 | E15: 4 | H15: Uso frequente pelo celular por público amador
B16: T08 | C16: Portabilidade | D16: 2 | E16: 4 | H16: Acesso por navegador, desktop e celular
B17: T09 | C17: Facilidade de manutenção | D17: 1 | E17: 3 | H17: Código organizado por casos de uso
B18: T10 | C18: Concorrência | D18: 1 | E18: 3 | H18: Vários usuários consultando e inscrevendo ao mesmo tempo
B19: T11 | C19: Características especiais de segurança | D19: 1 | E19: 3 | H19: Login e perfis de acesso (organizador, usuário, admin)
B20: T12 | C20: Acesso direto para terceiros | D20: 1 | E20: 2 | H20: Apenas o serviço de e-mail/push como integração
B21: T13 | C21: Facilidades especiais de treinamento | D21: 1 | E21: 1 | H21: Interface simples, sem treinamento formal
B22: Fator de Complexidade Técnica | E22: =0.6+(0.01*SUM(D9*E9,D10*E10,D11*E11,D12*E12,D13*E13,D14*E14,D15*E15,D16*E16,D17*E17,D18*E18,D19*E19,D20*E20,D21*E21)) -> 0.99
B26: Influência Ambiental
B27: ID | C27: Descrição | F27: Peso | G27: Influência | H27: Justificativa / premissa
B28: F01 | C28: Familiaridade com o Processo de Desenvolvimento de Software | F28: 1.5 | G28: 3 | H28: Premissa: equipe com conhecimento básico do processo (ajustar)
B29: F02 | C29: Experiência na Aplicação | F29: 0.5 | G29: 2 | H29: Premissa: primeiro projeto neste domínio (ajustar)
B30: F03 | C30: Experiência em Programação Orientada a Objetos | F30: 1 | G30: 3 | H30: Premissa: experiência intermediária em POO (ajustar)
B31: F04 | C31: Capacidade do Líder de Projeto | F31: 0.5 | G31: 3 | H31: Premissa: liderança intermediária (ajustar)
B32: F05 | C32: Motivação | F32: 1 | G32: 4 | H32: Premissa: equipe motivada (ajustar)
B33: F06 | C33: Requisitos estáveis | F33: 2 | G33: 4 | H33: Escopo fechado por release, com requisitos estáveis
B34: F07 | C34: Trabalhadores com dedicação parcial | F34: -1 | G34: 4 | H34: Premissa: equipe com dedicação parcial (ajustar)
B35: F08 | C35: Dificuldade da Linguagem de Programação | F35: -1 | G35: 2 | H35: Premissa: linguagem de dificuldade moderada (ajustar)
B36: Fator de Complexidade Ambiental | G36: =1.4+(-0.03*SUM(F28*G28,F29*G29,F30*G30,F31*G31,F32*G32,F33*G33,F34*G34,F35*G35)) -> 0.92

Sheet dadoshistoricos
B1: Base histórica de Projetos
B5: Projetos | C5: Tamanho | D5: Horas Reais | E5: Prospecção | F5: Análise e Projeto | G5: Planejamento | H5: Desenvolvimento | I5: Fechamento | J5: Mon.Controle | K5: Cont. Mud. | L5: Produtividade
B6: Projeto 01 | C6: 190 | D6: =SUM(E6:K6) -> 323 | E6: 12 | F6: 40 | G6: 12 | H6: 200 | I6: 10 | J6: 25 | K6: 24 | L6: =D6/C6 -> 1.7
B7: Projeto 02 | C7: 130 | D7: =SUM(E7:K7) -> 191 | E7: 10 | F7: 60 | G7: 15 | H7: 50 | I7: 10 | J7: 30 | K7: 16 | L7: =D7/C7 -> 1.4692308
B8: Projeto 03 | C8: 140 | D8: =SUM(E8:K8) -> 230 | E8: 9 | F8: 45 | G8: 16 | H8: 100 | I8: 12 | J8: 32 | K8: 16 | L8: =D8/C8 -> 1.6428571
B9: Projeto 04 | C9: 125 | D9: =SUM(E9:K9) -> 268 | E9: 11 | F9: 40 | G9: 16 | H9: 150 | I9: 8 | J9: 35 | K9: 8 | L9: =D9/C9 -> 2.144
B29: Total de horas por fase | D29: =SUM(D6:D28) -> 1012 | E29: =SUM(E6:E28) -> 42 | F29: =SUM(F6:F28) -> 185 | G29: =SUM(G6:G28) -> 59 | H29: =SUM(H6:H28) -> 500 | I29: =SUM(I6:I28) -> 40 | J29: =SUM(J6:J28) -> 122 | K29: =SUM(K6:K28) -> 64
J30: Produtividade média | L30: 4
B31: % de esforço por fases | E31: =(E29*1)/$D$29 -> 0.041501976 | F31: =(F29*1)/$D$29 -> 0.18280632 | G31: =(G29*1)/$D$29 -> 0.058300395 | H31: =(H29*1)/$D$29 -> 0.49407115 | I31: =(I29*1)/$D$29 -> 0.039525692 | J31: =(J29*1)/$D$29 -> 0.12055336 | K31: =(K29*1)/$D$29 -> 0.063241107 | L31: =SUM(E31:K31) -> 1
B33: Projeto atual (estimativa vigente, vinda da aba Geral) - não entra nos totais nem na média acima
B34: Projetos | C34: Tamanho | D34: Horas Reais | E34: Prospecção | F34: Análise e Projeto | G34: Planejamento | H34: Desenvolvimento | I34: Fechamento | J34: Mon.Controle | K34: Cont. Mud. | L34: Produtividade
B35: Arena Local (estimado) | C35: =Geral!E13 -> 100 | D35: =SUM(E35:K35) -> 400 | E35: =Geral!J13 -> 16.600791 | F35: =Geral!J14+Geral!J15 -> 73.12253 | G35: =Geral!J16 -> 23.320158 | H35: =Geral!J17 -> 197.62846 | I35: =Geral!J19 -> 15.810277 | J35: =Geral!J18 -> 48.221344 | K35: =Geral!J20 -> 25.296443 | L35: =D35/C35 -> 4
B36: % de esforço por fases (projeto atual) | E36: =E35/$D$35 -> 0.041501976 | F36: =F35/$D$35 -> 0.18280632 | G36: =G35/$D$35 -> 0.058300395 | H36: =H35/$D$35 -> 0.49407115 | I36: =I35/$D$35 -> 0.039525692 | J36: =J35/$D$35 -> 0.12055336 | K36: =K35/$D$35 -> 0.063241107 | L36: =SUM(E36:K36) -> 1
B37: Produtividade média da base (Projetos 01 a 04), calculada | L37: =AVERAGE(L6:L9) -> 1.739022
B38: Obs.: a produtividade adotada (L30 = 4 h/PCU, valor azul) fica acima da média calculada da base (~3,1 h/PCU), o que deixa o projeto com folga. As horas reais dos Projetos 01 a 04 não foram alteradas.

Sheet Premissas
B1: Premissas e parâmetros do cronograma
B4: Horas produtivas por pessoa/dia | C4: 6
B5: % da fase de Desenvolvimento para implementação | C5: 0.8
B6: % da fase de Desenvolvimento para testes (Selenium) e bugs | C6: =1-C5 -> 0.2
B7: Data de início do projeto | C7: 46313
B9: Feriados (excluídos dos dias úteis) | C9: Descrição
B10: 46328 | C10: Finados (segunda-feira)

Sheet Cronograma
B1: Cronograma do Projeto Arena Local
B3: Legenda de status (coluna M e barras do Gantt): | D3: Verde = Pronto | E3: Amarelo = Planejado | H3: Vermelho = Atrasado
M4: Marco | N4: {=IF(COUNTIF(Releases!$D$6:$D$10,N5)=0,"",IF(COUNTIF(Releases!$D$6:$D$10,N5)=1,INDEX(Releases!$A$6:$A$10,MATCH(N5,Releases!$D$6:$D$10,0)),INDEX(Releases!$A$6:$A$10,MATCH(N5,Releases!$D$6:$D$10,0))&"-"&RIGHT(INDEX(Releases!$A$6:$A$10,MATCH(N5,Releases!$D$6:$D$10,0)+COUNTIF(Releases!$D$6:$D$10,N5)-1),2)))} | O4: {=IF(COUNTIF(Releases!$D$6:$D$10,O5)=0,"",IF(COUNTIF(Releases!$D$6:$D$10,O5)=1,INDEX(Releases!$A$6:$A$10,MATCH(O5,Releases!$D$6:$D$10,0)),INDEX(Releases!$A$6:$A$10,MATCH(O5,Releases!$D$6:$D$10,0))&"-"&RIGHT(INDEX(Releases!$A$6:$A$10,MATCH(O5,Releases!$D$6:$D$10,0)+COUNTIF(Releases!$D$6:$D$10,O5)-1),2)))} -> R00 | P4: {=IF(COUNTIF(Releases!$D$6:$D$10,P5)=0,"",IF(COUNTIF(Releases!$D$6:$D$10,P5)=1,INDEX(Releases!$A$6:$A$10,MATCH(P5,Releases!$D$6:$D$10,0)),INDEX(Releases!$A$6:$A$10,MATCH(P5,Releases!$D$6:$D$10,0))&"-"&RIGHT(INDEX(Releases!$A$6:$A$10,MATCH(P5,Releases!$D$6:$D$10,0)+COUNTIF(Releases!$D$6:$D$10,P5)-1),2)))} | Q4: {=IF(COUNTIF(Releases!$D$6:$D$10,Q5)=0,"",IF(COUNTIF(Releases!$D$6:$D$10,Q5)=1,INDEX(Releases!$A$6:$A$10,MATCH(Q5,Releases!$D$6:$D$10,0)),INDEX(Releases!$A$6:$A$10,MATCH(Q5,Releases!$D$6:$D$10,0))&"-"&RIGHT(INDEX(Releases!$A$6:$A$10,MATCH(Q5,Releases!$D$6:$D$10,0)+COUNTIF(Releases!$D$6:$D$10,Q5)-1),2)))} | R4: {=IF(COUNTIF(Releases!$D$6:$D$10,R5)=0,"",IF(COUNTIF(Releases!$D$6:$D$10,R5)=1,INDEX(Releases!$A$6:$A$10,MATCH(R5,Releases!$D$6:$D$10,0)),INDEX(Releases!$A$6:$A$10,MATCH(R5,Releases!$D$6:$D$10,0))&"-"&RIGHT(INDEX(Releases!$A$6:$A$10,MATCH(R5,Releases!$D$6:$D$10,0)+COUNTIF(Releases!$D$6:$D$10,R5)-1),2)))} | S4: {=IF(COUNTIF(Releases!$D$6:$D$10,S5)=0,"",IF(COUNTIF(Releases!$D$6:$D$10,S5)=1,INDEX(Releases!$A$6:$A$10,MATCH(S5,Releases!$D$6:$D$10,0)),INDEX(Releases!$A$6:$A$10,MATCH(S5,Releases!$D$6:$D$10,0))&"-"&RIGHT(INDEX(Releases!$A$6:$A$10,MATCH(S5,Releases!$D$6:$D$10,0)+COUNTIF(Releases!$D$6:$D$10,S5)-1),2)))} | T4: {=IF(COUNTIF(Releases!$D$6:$D$10,T5)=0,"",IF(COUNTIF(Releases!$D$6:$D$10,T5)=1,INDEX(Releases!$A$6:$A$10,MATCH(T5,Releases!$D$6:$D$10,0)),INDEX(Releases!$A$6:$A$10,MATCH(T5,Releases!$D$6:$D$10,0))&"-"&RIGHT(INDEX(Releases!$A$6:$A$10,MATCH(T5,Releases!$D$6:$D$10,0)+COUNTIF(Releases!$D$6:$D$10,T5)-1),2)))} | U4: {=IF(COUNTIF(Releases!$D$6:$D$10,U5)=0,"",IF(COUNTIF(Releases!$D$6:$D$10,U5)=1,INDEX(Releases!$A$6:$A$10,MATCH(U5,Releases!$D$6:$D$10,0)),INDEX(Releases!$A$6:$A$10,MATCH(U5,Releases!$D$6:$D$10,0))&"-"&RIGHT(INDEX(Releases!$A$6:$A$10,MATCH(U5,Releases!$D$6:$D$10,0)+COUNTIF(Releases!$D$6:$D$10,U5)-1),2)))} | ... AJ4: {=IF(COUNTIF(Releases!$D$6:$D$10,AJ5)=0,"",IF(COUNTIF(Releases!$D$6:$D$10,AJ5)=1,INDEX(Releases!$A$6:$A$10,MATCH(AJ5,Releases!$D$6:$D$10,0)),INDEX(Releases!$A$6:$A$10,MATCH(AJ5,Releases!$D$6:$D$10,0))&"-"&RIGHT(INDEX(Releases!$A$6:$A$10,MATCH(AJ5,Releases!$D$6:$D$10,0)+COUNTIF(Releases!$D$6:$D$10,AJ5)-1),2)))} -> R01-04
A5: ID | B5: Atividade | C5: Release | D5: Fase | E5: Tipo | F5: Início | G5: Fim | H5: Dias úteis | I5: % da fase | J5: Horas | K5: Pts UC | L5: Pts release (testes) | M5: Status | N5: =WORKDAY(Premissas!$C$7-1,1,Premissas!$B$10:$B$14) -> 46314 | O5: =WORKDAY(N5,1,Premissas!$B$10:$B$14) -> 46315 | P5: =WORKDAY(O5,1,Premissas!$B$10:$B$14) -> 46316 | Q5: =WORKDAY(P5,1,Premissas!$B$10:$B$14) -> 46317 | R5: =WORKDAY(Q5,1,Premissas!$B$10:$B$14) -> 46318 | S5: =WORKDAY(R5,1,Premissas!$B$10:$B$14) -> 46321 | T5: =WORKDAY(S5,1,Premissas!$B$10:$B$14) -> 46322 | U5: =WORKDAY(T5,1,Premissas!$B$10:$B$14) -> 46323 | V5: =WORKDAY(U5,1,Premissas!$B$10:$B$14) -> 46324 | ... AJ5: =WORKDAY(AI5,1,Premissas!$B$10:$B$14) -> 46345
A6: Release 00 - Documentação (18/10 a 20/10)
A7: 1 | B7: Levantamento de escopo, visão e partes interessadas | C7: R00 | D7: Fase de Prospecção | E7: Documento | F7: 46313 | G7: 46314 | H7: =NETWORKDAYS(F7,G7,Premissas!$B$10:$B$14) -> 1 | I7: 0.6 | J7: {=INDEX(Geral!$J$13:$J$20,MATCH(D7,Geral!$G$13:$G$20,0))*I7} -> 9.9604743 | M7: Pronto
A8: 2 | B8: Identificação inicial de atores e funcionalidades | C8: R00 | D8: Fase de Prospecção | E8: Documento | F8: 46313 | G8: 46314 | H8: =NETWORKDAYS(F8,G8,Premissas!$B$10:$B$14) -> 1 | I8: 0.4 | J8: {=INDEX(Geral!$J$13:$J$20,MATCH(D8,Geral!$G$13:$G$20,0))*I8} -> 6.6403162 | M8: Pronto
A9: 3 | B9: Elaborar DRE (requisitos funcionais RFC/RFS) | C9: R00 | D9: Fase de Análise | E9: Documento | F9: 46313 | G9: 46315 | H9: =NETWORKDAYS(F9,G9,Premissas!$B$10:$B$14) -> 2 | I9: 0.45 | J9: {=INDEX(Geral!$J$13:$J$20,MATCH(D9,Geral!$G$13:$G$20,0))*I9} -> 26.324111 | M9: Pronto
A10: 4 | B10: Matriz de Rastreabilidade Bidirecional | C10: R00 | D10: Fase de Análise | E10: Documento | F10: 46315 | G10: 46315 | H10: =NETWORKDAYS(F10,G10,Premissas!$B$10:$B$14) -> 1 | I10: 0.15 | J10: {=INDEX(Geral!$J$13:$J$20,MATCH(D10,Geral!$G$13:$G$20,0))*I10} -> 8.7747036 | M10: Pronto
A11: 5 | B11: Estimativa definitiva de tamanho (PCU) | C11: R00 | D11: Fase de Planejamento | E11: Documento | F11: 46313 | G11: 46314 | H11: =NETWORKDAYS(F11,G11,Premissas!$B$10:$B$14) -> 1 | I11: 0.15 | J11: {=INDEX(Geral!$J$13:$J$20,MATCH(D11,Geral!$G$13:$G$20,0))*I11} -> 3.4980237 | M11: Pronto
A12: 6 | B12: Cronograma do projeto | C12: R00 | D12: Fase de Planejamento | E12: Documento | F12: 46314 | G12: 46315 | H12: =NETWORKDAYS(F12,G12,Premissas!$B$10:$B$14) -> 2 | I12: 0.2 | J12: {=INDEX(Geral!$J$13:$J$20,MATCH(D12,Geral!$G$13:$G$20,0))*I12} -> 4.6640316 | M12: Pronto
A13: 7 | B13: Plano de projeto | C13: R00 | D13: Fase de Planejamento | E13: Documento | F13: 46314 | G13: 46315 | H13: =NETWORKDAYS(F13,G13,Premissas!$B$10:$B$14) -> 2 | I13: 0.35 | J13: {=INDEX(Geral!$J$13:$J$20,MATCH(D13,Geral!$G$13:$G$20,0))*I13} -> 8.1620553 | M13: Pronto
A14: 8 | B14: Definir rotina de acompanhamento e métricas | C14: R00 | D14: Processo de Monitoramento e Controle | E14: Gestão | F14: 46315 | G14: 46315 | H14: =NETWORKDAYS(F14,G14,Premissas!$B$10:$B$14) -> 1 | I14: 0.1 | J14: {=INDEX(Geral!$J$13:$J$20,MATCH(D14,Geral!$G$13:$G$20,0))*I14} -> 4.8221344 | M14: Pronto
A15: Release 01 - 2 CRUDs (21/10 a 19/11)
A16: 9 | B16: Configurar repositório (SVN/GIT), Mantis/Bugzilla e Selenium | C16: R01 | D16: Fase de Planejamento | E16: Gestão | F16: 46316 | G16: 46317 | H16: =NETWORKDAYS(F16,G16,Premissas!$B$10:$B$14) -> 2 | I16: 0.3 | J16: {=INDEX(Geral!$J$13:$J$20,MATCH(D16,Geral!$G$13:$G$20,0))*I16} -> 6.9960474 | M16: Planejado
A17: 10 | B17: Arquitetura, tecnologias e padrões de projeto | C17: R01 | D17: Fase de Projeto | E17: Projeto | F17: 46316 | G17: 46317 | H17: =NETWORKDAYS(F17,G17,Premissas!$B$10:$B$14) -> 2 | I17: 0.4 | J17: {=INDEX(Geral!$J$13:$J$20,MATCH(D17,Geral!$G$13:$G$20,0))*I17} -> 5.8498024 | M17: Planejado
A18: 11 | B18: Modelo de dados e protótipos de tela (RFC01, RFC02) | C18: R01 | D18: Fase de Projeto | E18: Projeto | F18: 46317 | G18: 46318 | H18: =NETWORKDAYS(F18,G18,Premissas!$B$10:$B$14) -> 2 | I18: 0.2 | J18: {=INDEX(Geral!$J$13:$J$20,MATCH(D18,Geral!$G$13:$G$20,0))*I18} -> 2.9249012 | M18: Planejado
A19: 12 | B19: Refinar requisitos e atualizar MRB (R01) | C19: R01 | D19: Fase de Análise | E19: Documento | F19: 46317 | G19: 46318 | H19: =NETWORKDAYS(F19,G19,Premissas!$B$10:$B$14) -> 2 | I19: 0.1 | J19: {=INDEX(Geral!$J$13:$J$20,MATCH(D19,Geral!$G$13:$G$20,0))*I19} -> 5.8498024 | M19: Planejado
A20: 13 | B20: Implementar [RFC01] Manter Usuário | C20: R01 | D20: Fase de Desenvolvimento | E20: CRUD | F20: 46322 | G20: 46323 | H20: =NETWORKDAYS(F20,G20,Premissas!$B$10:$B$14) -> 2 | I20: =Premissas!$C$5*K20/UC!$D$10 -> 0.044444444 | J20: {=INDEX(Geral!$J$13:$J$20,MATCH(D20,Geral!$G$13:$G$20,0))*I20} -> 8.783487 | K20: {=INDEX(UC!$C$7:$C$9,MATCH(UC!$D$13,UC!$B$7:$B$9,0))} -> 5 | M20: Planejado
A21: 14 | B21: Implementar [RFC02] Manter Campeonato | C21: R01 | D21: Fase de Desenvolvimento | E21: CRUD | F21: 46322 | G21: 46323 | H21: =NETWORKDAYS(F21,G21,Premissas!$B$10:$B$14) -> 2 | I21: =Premissas!$C$5*K21/UC!$D$10 -> 0.088888889 | J21: {=INDEX(Geral!$J$13:$J$20,MATCH(D21,Geral!$G$13:$G$20,0))*I21} -> 17.566974 | K21: {=INDEX(UC!$C$7:$C$9,MATCH(UC!$D$14,UC!$B$7:$B$9,0))} -> 10 | M21: Planejado
A22: 15 | B22: Testes com Selenium e registro de bugs (Mantis/Bugzilla) - R01 | C22: R01 | D22: Fase de Desenvolvimento | E22: Testes | F22: 46324 | G22: 46324 | H22: =NETWORKDAYS(F22,G22,Premissas!$B$10:$B$14) -> 1 | I22: =Premissas!$C$6*L22/UC!$D$10 -> 0.033333333 | J22: {=INDEX(Geral!$J$13:$J$20,MATCH(D22,Geral!$G$13:$G$20,0))*I22} -> 6.5876153 | L22: =SUMIFS($K$6:$K$80,$C$6:$C$80,C22) -> 15 | M22: Planejado
A23: 16 | B23: Atualizar cronograma com dados de execução e salvar baseline (SVN/GIT) - R01 | C23: R01 | D23: Processo de Monitoramento e Controle | E23: Gestão | F23: 46345 | G23: 46345 | H23: =NETWORKDAYS(F23,G23,Premissas!$B$10:$B$14) -> 1 | I23: 0.225 | J23: {=INDEX(Geral!$J$13:$J$20,MATCH(D23,Geral!$G$13:$G$20,0))*I23} -> 10.849802 | M23: Planejado
A24: 17 | B24: Controle de mudanças - R01 | C24: R01 | D24: Processo Controle de mudanças | E24: Gestão | F24: 46345 | G24: 46345 | H24: =NETWORKDAYS(F24,G24,Premissas!$B$10:$B$14) -> 1 | I24: 0.25 | J24: {=INDEX(Geral!$J$13:$J$20,MATCH(D24,Geral!$G$13:$G$20,0))*I24} -> 6.3241107 | M24: Planejado
A25: Release 02 - 4 CRUDs acumulados (30/10 a 19/11)
A26: 18 | B26: Modelo de dados e protótipos de tela (RFC03, RFC04) | C26: R02 | D26: Fase de Projeto | E26: Projeto | F26: 46325 | G26: 46329 | H26: =NETWORKDAYS(F26,G26,Premissas!$B$10:$B$14) -> 2 | I26: 0.15 | J26: {=INDEX(Geral!$J$13:$J$20,MATCH(D26,Geral!$G$13:$G$20,0))*I26} -> 2.1936759 | M26: Planejado
A27: 19 | B27: Refinar requisitos e atualizar MRB (R02) | C27: R02 | D27: Fase de Análise | E27: Documento | F27: 46325 | G27: 46325 | H27: =NETWORKDAYS(F27,G27,Premissas!$B$10:$B$14) -> 1 | I27: 0.1 | J27: {=INDEX(Geral!$J$13:$J$20,MATCH(D27,Geral!$G$13:$G$20,0))*I27} -> 5.8498024 | M27: Planejado
A28: 20 | B28: Implementar [RFC03] Manter Campeonato | C28: R02 | D28: Fase de Desenvolvimento | E28: CRUD | F28: 46325 | G28: 46330 | H28: =NETWORKDAYS(F28,G28,Premissas!$B$10:$B$14) -> 3 | I28: =Premissas!$C$5*K28/UC!$D$10 -> 0.13333333 | J28: {=INDEX(Geral!$J$13:$J$20,MATCH(D28,Geral!$G$13:$G$20,0))*I28} -> 26.350461 | K28: {=INDEX(UC!$C$7:$C$9,MATCH(UC!$D$15,UC!$B$7:$B$9,0))} -> 15 | M28: Planejado
A29: 21 | B29: Implementar [RFC04] Manter Equipe | C29: R02 | D29: Fase de Desenvolvimento | E29: CRUD | F29: 46329 | G29: 46330 | H29: =NETWORKDAYS(F29,G29,Premissas!$B$10:$B$14) -> 2 | I29: =Premissas!$C$5*K29/UC!$D$10 -> 0.088888889 | J29: {=INDEX(Geral!$J$13:$J$20,MATCH(D29,Geral!$G$13:$G$20,0))*I29} -> 17.566974 | K29: {=INDEX(UC!$C$7:$C$9,MATCH(UC!$D$16,UC!$B$7:$B$9,0))} -> 10 | M29: Planejado
A30: 22 | B30: Testes com Selenium e registro de bugs (Mantis/Bugzilla) - R02 | C30: R02 | D30: Fase de Desenvolvimento | E30: Testes | F30: 46331 | G30: 46331 | H30: =NETWORKDAYS(F30,G30,Premissas!$B$10:$B$14) -> 1 | I30: =Premissas!$C$6*L30/UC!$D$10 -> 0.055555556 | J30: {=INDEX(Geral!$J$13:$J$20,MATCH(D30,Geral!$G$13:$G$20,0))*I30} -> 10.979359 | L30: =SUMIFS($K$6:$K$80,$C$6:$C$80,C30) -> 25 | M30: Planejado
A31: 23 | B31: Atualizar cronograma com dados de execução e salvar baseline (SVN/GIT) - R02 | C31: R02 | D31: Processo de Monitoramento e Controle | E31: Gestão | F31: 46345 | G31: 46345 | H31: =NETWORKDAYS(F31,G31,Premissas!$B$10:$B$14) -> 1 | I31: 0.225 | J31: {=INDEX(Geral!$J$13:$J$20,MATCH(D31,Geral!$G$13:$G$20,0))*I31} -> 10.849802 | M31: Planejado
A32: 24 | B32: Controle de mudanças - R02 | C32: R02 | D32: Processo Controle de mudanças | E32: Gestão | F32: 46345 | G32: 46345 | H32: =NETWORKDAYS(F32,G32,Premissas!$B$10:$B$14) -> 1 | I32: 0.25 | J32: {=INDEX(Geral!$J$13:$J$20,MATCH(D32,Geral!$G$13:$G$20,0))*I32} -> 6.3241107 | M32: Planejado
A33: Release 03 - 6 CRUDs acumulados + 1 relatório (06/11 a 19/11)
A34: 25 | B34: Modelo de dados e protótipos de tela (RFC05, RFC06, RFR01) | C34: R03 | D34: Fase de Projeto | E34: Projeto | F34: 46332 | G34: 46335 | H34: =NETWORKDAYS(F34,G34,Premissas!$B$10:$B$14) -> 2 | I34: 0.15 | J34: {=INDEX(Geral!$J$13:$J$20,MATCH(D34,Geral!$G$13:$G$20,0))*I34} -> 2.1936759 | M34: Planejado
A35: 26 | B35: Refinar requisitos e atualizar MRB (R03) | C35: R03 | D35: Fase de Análise | E35: Documento | F35: 46332 | G35: 46332 | H35: =NETWORKDAYS(F35,G35,Premissas!$B$10:$B$14) -> 1 | I35: 0.1 | J35: {=INDEX(Geral!$J$13:$J$20,MATCH(D35,Geral!$G$13:$G$20,0))*I35} -> 5.8498024 | M35: Planejado
A36: 27 | B36: Implementar [RFC05] Manter Partida | C36: R03 | D36: Fase de Desenvolvimento | E36: CRUD | F36: 46335 | G36: 46337 | H36: =NETWORKDAYS(F36,G36,Premissas!$B$10:$B$14) -> 3 | I36: =Premissas!$C$5*K36/UC!$D$10 -> 0.088888889 | J36: {=INDEX(Geral!$J$13:$J$20,MATCH(D36,Geral!$G$13:$G$20,0))*I36} -> 17.566974 | K36: {=INDEX(UC!$C$7:$C$9,MATCH(UC!$D$17,UC!$B$7:$B$9,0))} -> 10 | M36: Planejado
A37: 28 | B37: Implementar [RFC06] Manter Resultado de Partida | C37: R03 | D37: Fase de Desenvolvimento | E37: CRUD | F37: 46336 | G37: 46337 | H37: =NETWORKDAYS(F37,G37,Premissas!$B$10:$B$14) -> 2 | I37: =Premissas!$C$5*K37/UC!$D$10 -> 0.088888889 | J37: {=INDEX(Geral!$J$13:$J$20,MATCH(D37,Geral!$G$13:$G$20,0))*I37} -> 17.566974 | K37: {=INDEX(UC!$C$7:$C$9,MATCH(UC!$D$18,UC!$B$7:$B$9,0))} -> 10 | M37: Planejado
A38: 29 | B38: Implementar [RFR01] Relatório de Tabela de Jogos e Classificação | C38: R03 | D38: Fase de Desenvolvimento | E38: Relatório | F38: 46337 | G38: 46337 | H38: =NETWORKDAYS(F38,G38,Premissas!$B$10:$B$14) -> 1 | I38: =Premissas!$C$5*K38/UC!$D$10 -> 0.088888889 | J38: {=INDEX(Geral!$J$13:$J$20,MATCH(D38,Geral!$G$13:$G$20,0))*I38} -> 17.566974 | K38: {=INDEX(UC!$C$7:$C$9,MATCH(UC!$D$21,UC!$B$7:$B$9,0))} -> 10 | M38: Planejado
A39: 30 | B39: Testes com Selenium e registro de bugs (Mantis/Bugzilla) - R03 | C39: R03 | D39: Fase de Desenvolvimento | E39: Testes | F39: 46338 | G39: 46338 | H39: =NETWORKDAYS(F39,G39,Premissas!$B$10:$B$14) -> 1 | I39: =Premissas!$C$6*L39/UC!$D$10 -> 0.066666667 | J39: {=INDEX(Geral!$J$13:$J$20,MATCH(D39,Geral!$G$13:$G$20,0))*I39} -> 13.175231 | L39: =SUMIFS($K$6:$K$80,$C$6:$C$80,C39) -> 30 | M39: Planejado
A40: 31 | B40: Atualizar cronograma com dados de execução e salvar baseline (SVN/GIT) - R03 | C40: R03 | D40: Processo de Monitoramento e Controle | E40: Gestão | F40: 46345 | G40: 46345 | H40: =NETWORKDAYS(F40,G40,Premissas!$B$10:$B$14) -> 1 | I40: 0.225 | J40: {=INDEX(Geral!$J$13:$J$20,MATCH(D40,Geral!$G$13:$G$20,0))*I40} -> 10.849802 | M40: Planejado
A41: 32 | B41: Controle de mudanças - R03 | C41: R03 | D41: Processo Controle de mudanças | E41: Gestão | F41: 46345 | G41: 46345 | H41: =NETWORKDAYS(F41,G41,Premissas!$B$10:$B$14) -> 1 | I41: 0.25 | J41: {=INDEX(Geral!$J$13:$J$20,MATCH(D41,Geral!$G$13:$G$20,0))*I41} -> 6.3241107 | M41: Planejado
...

Sheet Releases
A1: Releases e conferência do cronograma
A2: Release 00 entregue em 20/10; Releases 01 a 04 com a mesma data de entrega (19/11). Conferência compara o planejado no Cronograma com o exigido.
A5: Release | B5: Início do período | C5: Início da janela | D5: Entrega (fim) | E5: Dias úteis do período | F5: Horas planejadas | G5: Pessoas necessárias (tempo integral) | H5: CRUDs acumulados exigidos | I5: CRUDs acumulados planejados | J5: Relatórios acumulados exigidos | K5: Relatórios acumulados planejados | L5: Conferência | M5: Entregas previstas
A6: R00 | B6: =Premissas!$C$7 -> 46313 | C6: 46313 | D6: 46315 | E6: =NETWORKDAYS(B6,D6,Premissas!$B$10:$B$14) -> 2 | F6: =SUMIF(Cronograma!$C$6:$C$51,A6,Cronograma!$J$6:$J$51) -> 72.84585 | G6: =F6/(E6*Premissas!$C$4) -> 6.0704875 | H6: 0 | I6: =COUNTIFS(Cronograma!$C$6:$C$51,A6,Cronograma!$E$6:$E$51,"CRUD") -> 0 | J6: 0 | K6: =COUNTIFS(Cronograma!$C$6:$C$51,A6,Cronograma!$E$6:$E$51,"Relatório") -> 0 | L6: =IF(AND(I6=H6,K6=J6),"OK","Verificar") -> OK | M6: DRE, Estimativa Definitiva de Tamanho, Cronograma, Matriz de Rastreabilidade Bidirecional e Plano de Projeto
A7: R01 | B7: =MINIFS(Cronograma!$F$6:$F$51,Cronograma!$C$6:$C$51,A7) -> 46316 | C7: 46343 | D7: 46345 | E7: =NETWORKDAYS(B7,D7,Premissas!$B$10:$B$14) -> 21 | F7: =SUMIF(Cronograma!$C$6:$C$51,A7,Cronograma!$J$6:$J$51) -> 71.732543 | G7: =F7/(E7*Premissas!$C$4) -> 0.5693059 | H7: 2 | I7: =COUNTIFS(Cronograma!$C$6:$C$51,A7,Cronograma!$E$6:$E$51,"CRUD")+I6 -> 2 | J7: 0 | K7: =COUNTIFS(Cronograma!$C$6:$C$51,A7,Cronograma!$E$6:$E$51,"Relatório")+K6 -> 0 | L7: =IF(AND(I7=H7,K7=J7),"OK","Verificar") -> OK | M7: 2 CRUDs + cronograma atualizado + baseline no SVN/GIT + testes Selenium + bugs no Mantis/Bugzilla
A8: R02 | B8: =MINIFS(Cronograma!$F$6:$F$51,Cronograma!$C$6:$C$51,A8) -> 46325 | C8: 46343 | D8: 46345 | E8: =NETWORKDAYS(B8,D8,Premissas!$B$10:$B$14) -> 14 | F8: =SUMIF(Cronograma!$C$6:$C$51,A8,Cronograma!$J$6:$J$51) -> 80.114185 | G8: =F8/(E8*Premissas!$C$4) -> 0.9537403 | H8: 4 | I8: =COUNTIFS(Cronograma!$C$6:$C$51,A8,Cronograma!$E$6:$E$51,"CRUD")+I7 -> 4 | J8: 0 | K8: =COUNTIFS(Cronograma!$C$6:$C$51,A8,Cronograma!$E$6:$E$51,"Relatório")+K7 -> 0 | L8: =IF(AND(I8=H8,K8=J8),"OK","Verificar") -> OK | M8: 4 CRUDs + cronograma + baseline no SVN/GIT + testes Selenium + bugs no Mantis/Bugzilla
A9: R03 | B9: =MINIFS(Cronograma!$F$6:$F$51,Cronograma!$C$6:$C$51,A9) -> 46332 | C9: 46343 | D9: 46345 | E9: =NETWORKDAYS(B9,D9,Premissas!$B$10:$B$14) -> 10 | F9: =SUMIF(Cronograma!$C$6:$C$51,A9,Cronograma!$J$6:$J$51) -> 91.093544 | G9: =F9/(E9*Premissas!$C$4) -> 1.5182257 | H9: 6 | I9: =COUNTIFS(Cronograma!$C$6:$C$51,A9,Cronograma!$E$6:$E$51,"CRUD")+I8 -> 6 | J9: 1 | K9: =COUNTIFS(Cronograma!$C$6:$C$51,A9,Cronograma!$E$6:$E$51,"Relatório")+K8 -> 1 | L9: =IF(AND(I9=H9,K9=J9),"OK","Verificar") -> OK | M9: 6 CRUDs + 1 relatório + cronograma + baseline no SVN/GIT + testes Selenium + bugs no Mantis/Bugzilla
A10: R04 | B10: =MINIFS(Cronograma!$F$6:$F$51,Cronograma!$C$6:$C$51,A10) -> 46339 | C10: 46343 | D10: 46345 | E10: =NETWORKDAYS(B10,D10,Premissas!$B$10:$B$14) -> 5 | F10: =SUMIF(Cronograma!$C$6:$C$51,A10,Cronograma!$J$6:$J$51) -> 84.213878 | G10: =F10/(E10*Premissas!$C$4) -> 2.8071293 | H10: 8 | I10: =COUNTIFS(Cronograma!$C$6:$C$51,A10,Cronograma!$E$6:$E$51,"CRUD")+I9 -> 8 | J10: 1 | K10: =COUNTIFS(Cronograma!$C$6:$C$51,A10,Cronograma!$E$6:$E$51,"Relatório")+K9 -> 1 | L10: =IF(AND(I10=H10,K10=J10),"OK","Verificar") -> OK | M10: 8 CRUDs + 1 relatório + cronograma + baseline no SVN/GIT + testes Selenium + bugs no Mantis/Bugzilla
A11: Total | E11: =NETWORKDAYS(MIN(B6:B10),MAX(D6:D10),Premissas!$B$10:$B$14) -> 23 | F11: =SUM(F6:F10) -> 400 | G11: =F11/(E11*Premissas!$C$4) -> 2.8985507
A14: Conferência por fase (horas da estimativa x horas alocadas no cronograma)
A15: Fase | D15: Horas (aba Geral) | E15: Horas no cronograma | F15: % alocado | G15: Conferência
A16: =Geral!G13 -> Fase de Prospecção | D16: =Geral!J13 -> 16.600791 | E16: =SUMIF(Cronograma!$D$6:$D$51,A16,Cronograma!$J$6:$J$51) -> 16.600791 | F16: =IF(D16=0,0,E16/D16) -> 1 | G16: =IF(ABS(E16-D16)<0.01,"OK","Verificar") -> OK
A17: =Geral!G14 -> Fase de Análise | D17: =Geral!J14 -> 58.498024 | E17: =SUMIF(Cronograma!$D$6:$D$51,A17,Cronograma!$J$6:$J$51) -> 58.498024 | F17: =IF(D17=0,0,E17/D17) -> 1 | G17: =IF(ABS(E17-D17)<0.01,"OK","Verificar") -> OK
A18: =Geral!G15 -> Fase de Projeto | D18: =Geral!J15 -> 14.624506 | E18: =SUMIF(Cronograma!$D$6:$D$51,A18,Cronograma!$J$6:$J$51) -> 14.624506 | F18: =IF(D18=0,0,E18/D18) -> 1 | G18: =IF(ABS(E18-D18)<0.01,"OK","Verificar") -> OK
A19: =Geral!G16 -> Fase de Planejamento | D19: =Geral!J16 -> 23.320158 | E19: =SUMIF(Cronograma!$D$6:$D$51,A19,Cronograma!$J$6:$J$51) -> 23.320158 | F19: =IF(D19=0,0,E19/D19) -> 1 | G19: =IF(ABS(E19-D19)<0.01,"OK","Verificar") -> OK
A20: =Geral!G17 -> Fase de Desenvolvimento | D20: =Geral!J17 -> 197.62846 | E20: =SUMIF(Cronograma!$D$6:$D$51,A20,Cronograma!$J$6:$J$51) -> 197.62846 | F20: =IF(D20=0,0,E20/D20) -> 1 | G20: =IF(ABS(E20-D20)<0.01,"OK","Verificar") -> OK
A21: =Geral!G18 -> Processo de Monitoramento e Controle | D21: =Geral!J18 -> 48.221344 | E21: =SUMIF(Cronograma!$D$6:$D$51,A21,Cronograma!$J$6:$J$51) -> 48.221344 | F21: =IF(D21=0,0,E21/D21) -> 1 | G21: =IF(ABS(E21-D21)<0.01,"OK","Verificar") -> OK
A22: =Geral!G19 -> Fase de Fechamento | D22: =Geral!J19 -> 15.810277 | E22: =SUMIF(Cronograma!$D$6:$D$51,A22,Cronograma!$J$6:$J$51) -> 15.810277 | F22: =IF(D22=0,0,E22/D22) -> 1 | G22: =IF(ABS(E22-D22)<0.01,"OK","Verificar") -> OK
A23: =Geral!G20 -> Processo Controle de mudanças | D23: =Geral!J20 -> 25.296443 | E23: =SUMIF(Cronograma!$D$6:$D$51,A23,Cronograma!$J$6:$J$51) -> 25.296443 | F23: =IF(D23=0,0,E23/D23) -> 1 | G23: =IF(ABS(E23-D23)<0.01,"OK","Verificar") -> OK
A24: Total | D24: =SUM(D16:D23) -> 400 | E24: =SUM(E16:E23) -> 400 | G24: =IF(ABS(E24-Geral!J21)<0.01,"OK","Verificar") -> OK
